Workbook

Sheet Leave Tracker
A1: Employee ID | B1: Name | C1: Leave Type | D1: Start Date | E1: End Date | F1: Number of Days | G1: Rejoining Date | H1: Leave Status | I1: Status as on | J1: Leave Balance | K1: Current Leave Balance | L1: Sort Order | M1: Filter Leave Type: | N1: Rejoin alert | O1: Extende Days | P1: Remanrk
A2: 2120 | B2: =IFERROR(VLOOKUP(A2,'[1]Master File'!$A$2:$C$312,3,0)," ") -> Siraj Ahmad | C2: Annual Leave | D2: 45607 | E2: 45667 | F2: =IF(OR(D2="",E2 =""), "", E2 - D2+ 1) -> 61 | G2: 45672 | H2: =IF(G2="", "Not Rejoined", "Rejoined") -> Rejoined | I2: =IF(AND(G2="", E2="", D2=""), "", IF(D2>TODAY(), "Applied", IF(G2<>"", IF(G2<E2, "Early Rejoin", "Rejoined"), IF(E2>TODAY(), "On Leave", "Not Rejoined")))) -> Rejoined | L2: =IF(H2="Not Rejoined", 0, 1) -> 1 | M2: =IF(OR(#REF!="", C2=#REF!), 1, 0) -> #REF! | N2: =IF(AND(E2<>"", E2>=TODAY(), E2<=TODAY()+3), "Rejoin Follow Up", "") | O2: =IF(AND(G2<>"", G2 > E2, (G2 - E2) <> 1), G2 - E2, "") -> 5
A3: 2554 | B3: =IFERROR(VLOOKUP(A3,'[1]Master File'!$A$2:$C$312,3,0)," ") -> Sheikh Shahid | C3: Annual Leave | D3: 45611 | E3: 45670 | F3: =IF(OR(D3="",E3 =""), "", E3 - D3+ 1) -> 60 | G3: 45672 | I3: =IF(AND(G3="", E3="", D3=""), "", IF(D3>TODAY(), "Applied", IF(G3<>"", IF(G3<E3, "Early Rejoin", "Rejoined"), IF(E3>TODAY(), "On Leave", "Not Rejoined")))) -> Rejoined | N3: =IF(AND(E3<>"", E3>=TODAY(), E3<=TODAY()+3), "Rejoin Follow Up", "") | O3: =IF(AND(G3<>"", G3 > E3, (G3 - E3) <> 1), G3 - E3, "") -> 2
A4: 232 | B4: =IFERROR(VLOOKUP(A4,'[1]Master File'!$A$2:$C$312,3,0)," ") -> Ruhul Amin Haian Saiyal | C4: Annual Leave | D4: 45613 | E4: 45672 | F4: =IF(OR(D4="",E4 =""), "", E4 - D4+ 1) -> 60 | G4: 45676 | H4: =IF(G4="", "Not Rejoined", "Rejoined") -> Rejoined | I4: =IF(AND(G4="", E4="", D4=""), "", IF(D4>TODAY(), "Applied", IF(G4<>"", IF(G4<E4, "Early Rejoin", "Rejoined"), IF(E4>TODAY(), "On Leave", "Not Rejoined")))) -> Rejoined | J4: =IFERROR(VLOOKUP(A4,'[1]Master File'!$A$2:$Q$312,17,0)," ") -> 74.5 | K4: =IF(C4="Annual Leave",J4-F4," ") -> 14.5 | L4: =IF(H4="Not Rejoined", 0, 1) -> 1 | M4: =IF(OR(#REF!="", C4=#REF!), 1, 0) -> #REF! | N4: =IF(AND(E4<>"", E4>=TODAY(), E4<=TODAY()+3), "Rejoin Follow Up", "") | O4: =IF(AND(G4<>"", G4 > E4, (G4 - E4) <> 1), G4 - E4, "") -> 4
A5: 2450 | B5: =IFERROR(VLOOKUP(A5,'[1]Master File'!$A$2:$C$312,3,0)," ") -> Najir Hussain | C5: Annual Leave | D5: 45614 | E5: 45673 | F5: =IF(OR(D5="",E5 =""), "", E5 - D5+ 1) -> 60 | G5: 45677 | H5: =IF(G5="", "Not Rejoined", "Rejoined") -> Rejoined | I5: =IF(AND(G5="", E5="", D5=""), "", IF(D5>TODAY(), "Applied", IF(G5<>"", IF(G5<E5, "Early Rejoin", "Rejoined"), IF(E5>TODAY(), "On Leave", "Not Rejoined")))) -> Rejoined | L5: =IF(H5="Not Rejoined", 0, 1) -> 1 | M5: =IF(OR(#REF!="", C5=#REF!), 1, 0) -> #REF! | N5: =IF(AND(E5<>"", E5>=TODAY(), E5<=TODAY()+3), "Rejoin Follow Up", "") | O5: =IF(AND(G5<>"", G5 > E5, (G5 - E5) <> 1), G5 - E5, "") -> 4
A6: 1806 | B6: =IFERROR(VLOOKUP(A6,'[1]Master File'!$A$2:$C$312,3,0)," ") -> Saroj Kumar Mukhram | C6: Annual Leave | D6: 45614 | E6: 45673 | F6: =IF(OR(D6="",E6 =""), "", E6 - D6+ 1) -> 60 | G6: 45677 | I6: =IF(AND(G6="", E6="", D6=""), "", IF(D6>TODAY(), "Applied", IF(G6<>"", IF(G6<E6, "Early Rejoin", "Rejoined"), IF(E6>TODAY(), "On Leave", "Not Rejoined")))) -> Rejoined | N6: =IF(AND(E6<>"", E6>=TODAY(), E6<=TODAY()+3), "Rejoin Follow Up", "") | O6: =IF(AND(G6<>"", G6 > E6, (G6 - E6) <> 1), G6 - E6, "") -> 4
A7: 2628 | B7: =IFERROR(VLOOKUP(A7,'[1]Master File'!$A$2:$C$312,3,0)," ") -> Sona Kizhakudan Prince | C7: Annual Leave | D7: 45622 | E7: 45660 | F7: =IF(OR(D7="",E7 =""), "", E7 - D7+ 1) -> 39 | G7: 45660 | I7: =IF(AND(G7="", E7="", D7=""), "", IF(D7>TODAY(), "Applied", IF(G7<>"", IF(G7<E7, "Early Rejoin", "Rejoined"), IF(E7>TODAY(), "On Leave", "Not Rejoined")))) -> Rejoined | N7: =IF(AND(E7<>"", E7>=TODAY(), E7<=TODAY()+3), "Rejoin Follow Up", "") | O7: =IF(AND(G7<>"", G7 > E7, (G7 - E7) <> 1), G7 - E7, "")
A8: 2615 | B8: =IFERROR(VLOOKUP(A8,'[1]Master File'!$A$2:$C$312,3,0)," ") -> Qamar Zaman Muhammad Akmal | C8: Annual Leave | D8: 45629 | E8: 45674 | F8: =IF(OR(D8="",E8 =""), "", E8 - D8+ 1) -> 46 | G8: 45681 | I8: =IF(AND(G8="", E8="", D8=""), "", IF(D8>TODAY(), "Applied", IF(G8<>"", IF(G8<E8, "Early Rejoin", "Rejoined"), IF(E8>TODAY(), "On Leave", "Not Rejoined")))) -> Rejoined | N8: =IF(AND(E8<>"", E8>=TODAY(), E8<=TODAY()+3), "Rejoin Follow Up", "") | O8: =IF(AND(G8<>"", G8 > E8, (G8 - E8) <> 1), G8 - E8, "") -> 7
A9: 2599 | B9: =IFERROR(VLOOKUP(A9,'[1]Master File'!$A$2:$C$312,3,0)," ") -> Abdul Rahman | C9: Annual Leave | D9: 45630 | E9: 45675 | F9: =IF(OR(D9="",E9 =""), "", E9 - D9+ 1) -> 46 | G9: 45677 | I9: =IF(AND(G9="", E9="", D9=""), "", IF(D9>TODAY(), "Applied", IF(G9<>"", IF(G9<E9, "Early Rejoin", "Rejoined"), IF(E9>TODAY(), "On Leave", "Not Rejoined")))) -> Rejoined | N9: =IF(AND(E9<>"", E9>=TODAY(), E9<=TODAY()+3), "Rejoin Follow Up", "") | O9: =IF(AND(G9<>"", G9 > E9, (G9 - E9) <> 1), G9 - E9, "") -> 2
A10: 1016 | B10: =IFERROR(VLOOKUP(A10,'[1]Master File'!$A$2:$C$312,3,0)," ") -> Mohammed Abul Hasan | C10: Annual Leave | D10: 45635 | E10: 45694 | F10: =IF(OR(D10="",E10 =""), "", E10 - D10+ 1) -> 60 | G10: 45701 | H10: =IF(G10="", "Not Rejoined", "Rejoined") -> Rejoined | I10: =IF(AND(G10="", E10="", D10=""), "", IF(D10>TODAY(), "Applied", IF(G10<>"", IF(G10<E10, "Early Rejoin", "Rejoined"), IF(E10>TODAY(), "On Leave", "Not Rejoined")))) -> Rejoined | L10: =IF(H10="Not Rejoined", 0, 1) -> 1 | M10: =IF(OR(#REF!="", C10=#REF!), 1, 0) -> #REF! | N10: =IF(AND(E10<>"", E10>=TODAY(), E10<=TODAY()+3), "Rejoin Follow Up", "") | O10: =IF(AND(G10<>"", G10 > E10, (G10 - E10) <> 1), G10 - E10, "") -> 7
A11: 2635 | B11: =IFERROR(VLOOKUP(A11,'[1]Master File'!$A$2:$C$312,3,0)," ") -> Muhamed Minhaj Nayarkandy | C11: Annual Leave | D11: 45635 | E11: 45664 | F11: =IF(OR(D11="",E11 =""), "", E11 - D11+ 1) -> 30 | G11: 45673 | I11: =IF(AND(G11="", E11="", D11=""), "", IF(D11>TODAY(), "Applied", IF(G11<>"", IF(G11<E11, "Early Rejoin", "Rejoined"), IF(E11>TODAY(), "On Leave", "Not Rejoined")))) -> Rejoined | N11: =IF(AND(E11<>"", E11>=TODAY(), E11<=TODAY()+3), "Rejoin Follow Up", "") | O11: =IF(AND(G11<>"", G11 > E11, (G11 - E11) <> 1), G11 - E11, "") -> 9
A12: 2538 | B12: =IFERROR(VLOOKUP(A12,'[1]Master File'!$A$2:$C$312,3,0)," ") -> Rasel Iman Hossain | C12: Annual Leave | D12: 45642 | E12: 45701 | F12: =IF(OR(D12="",E12 =""), "", E12 - D12+ 1) -> 60 | G12: 45709 | I12: =IF(AND(G12="", E12="", D12=""), "", IF(D12>TODAY(), "Applied", IF(G12<>"", IF(G12<E12, "Early Rejoin", "Rejoined"), IF(E12>TODAY(), "On Leave", "Not Rejoined")))) -> Rejoined | N12: =IF(AND(E12<>"", E12>=TODAY(), E12<=TODAY()+3), "Rejoin Follow Up", "") | O12: =IF(AND(G12<>"", G12 > E12, (G12 - E12) <> 1), G12 - E12, "") -> 8
A13: 2614 | B13: =IFERROR(VLOOKUP(A13,'[1]Master File'!$A$2:$C$312,3,0)," ") -> Manish Kumar Yadav | C13: Emergency Leave | D13: 45656 | E13: 45702 | F13: =IF(OR(D13="",E13 =""), "", E13 - D13+ 1) -> 47 | G13: 45726 | I13: =IF(AND(G13="", E13="", D13=""), "", IF(D13>TODAY(), "Applied", IF(G13<>"", IF(G13<E13, "Early Rejoin", "Rejoined"), IF(E13>TODAY(), "On Leave", "Not Rejoined")))) -> Rejoined | N13: =IF(AND(E13<>"", E13>=TODAY(), E13<=TODAY()+3), "Rejoin Follow Up", "") | O13: =IF(AND(G13<>"", G13 > E13, (G13 - E13) <> 1), G13 - E13, "") -> 24
A14: 1106 | B14: =IFERROR(VLOOKUP(A14,'[1]Master File'!$A$2:$C$312,3,0)," ") -> Ram Chandra Pradhan | C14: Annual Leave | D14: 45656 | E14: 45715 | F14: =IF(OR(D14="",E14 =""), "", E14 - D14+ 1) -> 60 | G14: 45716 | I14: =IF(AND(G14="", E14="", D14=""), "", IF(D14>TODAY(), "Applied", IF(G14<>"", IF(G14<E14, "Early Rejoin", "Rejoined"), IF(E14>TODAY(), "On Leave", "Not Rejoined")))) -> Rejoined | N14: =IF(AND(E14<>"", E14>=TODAY(), E14<=TODAY()+3), "Rejoin Follow Up", "") | O14: =IF(AND(G14<>"", G14 > E14, (G14 - E14) <> 1), G14 - E14, "")
A15: 999 | B15: =IFERROR(VLOOKUP(A15,'[1]Master File'!$A$2:$C$312,3,0)," ") -> Gul Meen Khan Lal Meer Khan | C15: Annual Leave | D15: 45656 | E15: 45715 | F15: =IF(OR(D15="",E15 =""), "", E15 - D15+ 1) -> 60 | G15: 45775 | I15: =IF(AND(G15="", E15="", D15=""), "", IF(D15>TODAY(), "Applied", IF(G15<>"", IF(G15<E15, "Early Rejoin", "Rejoined"), IF(E15>TODAY(), "On Leave", "Not Rejoined")))) -> Rejoined | N15: =IF(AND(E15<>"", E15>=TODAY(), E15<=TODAY()+3), "Rejoin Follow Up", "") | O15: =IF(AND(G15<>"", G15 > E15, (G15 - E15) <> 1), G15 - E15, "") -> 60
A16: 2610 | B16: =IFERROR(VLOOKUP(A16,'[1]Master File'!$A$2:$C$312,3,0)," ") -> Natalia Kolieva | C16: Annual Leave | D16: 45656 | E16: 45660 | F16: =IF(OR(D16="",E16 =""), "", E16 - D16+ 1) -> 5 | G16: 45661 | I16: =IF(AND(G16="", E16="", D16=""), "", IF(D16>TODAY(), "Applied", IF(G16<>"", IF(G16<E16, "Early Rejoin", "Rejoined"), IF(E16>TODAY(), "On Leave", "Not Rejoined")))) -> Rejoined | N16: =IF(AND(E16<>"", E16>=TODAY(), E16<=TODAY()+3), "Rejoin Follow Up", "") | O16: =IF(AND(G16<>"", G16 > E16, (G16 - E16) <> 1), G16 - E16, "")
A17: 67 | B17: =IFERROR(VLOOKUP(A17,'[1]Master File'!$A$2:$C$312,3,0)," ") -> Esoj Jose | C17: Annual Leave | D17: 45659 | E17: 45688 | F17: =IF(OR(D17="",E17 =""), "", E17 - D17+ 1) -> 30 | G17: 45691 | I17: =IF(AND(G17="", E17="", D17=""), "", IF(D17>TODAY(), "Applied", IF(G17<>"", IF(G17<E17, "Early Rejoin", "Rejoined"), IF(E17>TODAY(), "On Leave", "Not Rejoined")))) -> Rejoined | N17: =IF(AND(E17<>"", E17>=TODAY(), E17<=TODAY()+3), "Rejoin Follow Up", "") | O17: =IF(AND(G17<>"", G17 > E17, (G17 - E17) <> 1), G17 - E17, "") -> 3
A18: 2240 | B18: =IFERROR(VLOOKUP(A18,'[1]Master File'!$A$2:$C$312,3,0)," ") -> Rifas Ansary Mohammed | C18: Annual Leave | D18: 45663 | E18: 45666 | F18: =IF(OR(D18="",E18 =""), "", E18 - D18+ 1) -> 4 | G18: 45667 | I18: =IF(AND(G18="", E18="", D18=""), "", IF(D18>TODAY(), "Applied", IF(G18<>"", IF(G18<E18, "Early Rejoin", "Rejoined"), IF(E18>TODAY(), "On Leave", "Not Rejoined")))) -> Rejoined | N18: =IF(AND(E18<>"", E18>=TODAY(), E18<=TODAY()+3), "Rejoin Follow Up", "") | O18: =IF(AND(G18<>"", G18 > E18, (G18 - E18) <> 1), G18 - E18, "")
A19: 2665 | B19: =IFERROR(VLOOKUP(A19,'[1]Master File'!$A$2:$C$312,3,0)," ") -> Manmeet Singh | C19: Emergency Leave | D19: 45666 | E19: 45677 | F19: =IF(OR(D19="",E19 =""), "", E19 - D19+ 1) -> 12 | I19: Overstay | N19: =IF(AND(E19<>"", E19>=TODAY(), E19<=TODAY()+3), "Rejoin Follow Up", "") | O19: =IF(AND(G19<>"", G19 > E19, (G19 - E19) <> 1), G19 - E19, "")
A20: 394 | B20: =IFERROR(VLOOKUP(A20,'[1]Master File'!$A$2:$C$312,3,0)," ") -> Kamal Hossain Tofazzal Mollah | C20: Annual Leave | D20: 45669 | E20: 45730 | F20: =IF(OR(D20="",E20 =""), "", E20 - D20+ 1) -> 62 | G20: 45730 | I20: =IF(AND(G20="", E20="", D20=""), "", IF(D20>TODAY(), "Applied", IF(G20<>"", IF(G20<E20, "Early Rejoin", "Rejoined"), IF(E20>TODAY(), "On Leave", "Not Rejoined")))) -> Rejoined | N20: =IF(AND(E20<>"", E20>=TODAY(), E20<=TODAY()+3), "Rejoin Follow Up", "") | O20: =IF(AND(G20<>"", G20 > E20, (G20 - E20) <> 1), G20 - E20, "")
A21: 2647 | B21: =IFERROR(VLOOKUP(A21,'[1]Master File'!$A$2:$C$312,3,0)," ") -> Sethu Kumar | C21: Annual Leave | D21: 45670 | E21: 45687 | F21: =IF(OR(D21="",E21 =""), "", E21 - D21+ 1) -> 18 | G21: 45688 | I21: =IF(AND(G21="", E21="", D21=""), "", IF(D21>TODAY(), "Applied", IF(G21<>"", IF(G21<E21, "Early Rejoin", "Rejoined"), IF(E21>TODAY(), "On Leave", "Not Rejoined")))) -> Rejoined | N21: =IF(AND(E21<>"", E21>=TODAY(), E21<=TODAY()+3), "Rejoin Follow Up", "") | O21: =IF(AND(G21<>"", G21 > E21, (G21 - E21) <> 1), G21 - E21, "")
A22: 1360 | B22: =IFERROR(VLOOKUP(A22,'[1]Master File'!$A$2:$C$312,3,0)," ") -> Buchi Babu Daram | C22: Annual Leave | D22: 45670 | E22: 45684 | F22: =IF(OR(D22="",E22 =""), "", E22 - D22+ 1) -> 15 | G22: 45685 | I22: =IF(AND(G22="", E22="", D22=""), "", IF(D22>TODAY(), "Applied", IF(G22<>"", IF(G22<E22, "Early Rejoin", "Rejoined"), IF(E22>TODAY(), "On Leave", "Not Rejoined")))) -> Rejoined | N22: =IF(AND(E22<>"", E22>=TODAY(), E22<=TODAY()+3), "Rejoin Follow Up", "") | O22: =IF(AND(G22<>"", G22 > E22, (G22 - E22) <> 1), G22 - E22, "")
A23: 2247 | B23: =IFERROR(VLOOKUP(A23,'[1]Master File'!$A$2:$C$312,3,0)," ") -> Ajaya Kumar | C23: Annual Leave | D23: 45670 | E23: 45730 | F23: =IF(OR(D23="",E23 =""), "", E23 - D23+ 1) -> 61 | G23: 45736 | I23: =IF(AND(G23="", E23="", D23=""), "", IF(D23>TODAY(), "Applied", IF(G23<>"", IF(G23<E23, "Early Rejoin", "Rejoined"), IF(E23>TODAY(), "On Leave", "Not Rejoined")))) -> Rejoined | N23: =IF(AND(E23<>"", E23>=TODAY(), E23<=TODAY()+3), "Rejoin Follow Up", "") | O23: =IF(AND(G23<>"", G23 > E23, (G23 - E23) <> 1), G23 - E23, "") -> 6
A24: 2315 | B24: =IFERROR(VLOOKUP(A24,'[1]Master File'!$A$2:$C$312,3,0)," ") -> Mandresh Khedan | C24: Annual Leave | D24: 45670 | E24: 45729 | F24: =IF(OR(D24="",E24 =""), "", E24 - D24+ 1) -> 60 | G24: 45738 | I24: =IF(AND(G24="", E24="", D24=""), "", IF(D24>TODAY(), "Applied", IF(G24<>"", IF(G24<E24, "Early Rejoin", "Rejoined"), IF(E24>TODAY(), "On Leave", "Not Rejoined")))) -> Rejoined | N24: =IF(AND(E24<>"", E24>=TODAY(), E24<=TODAY()+3), "Rejoin Follow Up", "") | O24: =IF(AND(G24<>"", G24 > E24, (G24 - E24) <> 1), G24 - E24, "") -> 9
A25: 14 | B25: =IFERROR(VLOOKUP(A25,'[1]Master File'!$A$2:$C$312,3,0)," ") -> Afroz Ali Khan Khan | C25: Annual Leave | D25: 45670 | E25: 45678 | F25: =IF(OR(D25="",E25 =""), "", E25 - D25+ 1) -> 9 | G25: 45679 | I25: =IF(AND(G25="", E25="", D25=""), "", IF(D25>TODAY(), "Applied", IF(G25<>"", IF(G25<E25, "Early Rejoin", "Rejoined"), IF(E25>TODAY(), "On Leave", "Not Rejoined")))) -> Rejoined | N25: =IF(AND(E25<>"", E25>=TODAY(), E25<=TODAY()+3), "Rejoin Follow Up", "") | O25: =IF(AND(G25<>"", G25 > E25, (G25 - E25) <> 1), G25 - E25, "")
A26: 2545 | B26: =IFERROR(VLOOKUP(A26,'[1]Master File'!$A$2:$C$312,3,0)," ") -> Mohammad Jamal Badiyar | C26: Annual Leave | D26: 45671 | E26: 45702 | F26: =IF(OR(D26="",E26 =""), "", E26 - D26+ 1) -> 32 | G26: 45708 | I26: =IF(AND(G26="", E26="", D26=""), "", IF(D26>TODAY(), "Applied", IF(G26<>"", IF(G26<E26, "Early Rejoin", "Rejoined"), IF(E26>TODAY(), "On Leave", "Not Rejoined")))) -> Rejoined | N26: =IF(AND(E26<>"", E26>=TODAY(), E26<=TODAY()+3), "Rejoin Follow Up", "") | O26: =IF(AND(G26<>"", G26 > E26, (G26 - E26) <> 1), G26 - E26, "") -> 6
A27: 2737 | B27: Anbu Vadivel Subbiah | C27: Emergency Leave | D27: 45671 | E27: 45678 | F27: =IF(OR(D27="",E27 =""), "", E27 - D27+ 1) -> 8 | G27: 45679 | I27: =IF(AND(G27="", E27="", D27=""), "", IF(D27>TODAY(), "Applied", IF(G27<>"", IF(G27<E27, "Early Rejoin", "Rejoined"), IF(E27>TODAY(), "On Leave", "Not Rejoined")))) -> Rejoined | N27: =IF(AND(E27<>"", E27>=TODAY(), E27<=TODAY()+3), "Rejoin Follow Up", "") | O27: =IF(AND(G27<>"", G27 > E27, (G27 - E27) <> 1), G27 - E27, "")
A28: 2550 | B28: =IFERROR(VLOOKUP(A28,'[1]Master File'!$A$2:$C$312,3,0)," ") -> Grasvin Grogory | C28: Annual Leave | D28: 45677 | E28: 45698 | F28: =IF(OR(D28="",E28 =""), "", E28 - D28+ 1) -> 22 | G28: 45719 | I28: =IF(AND(G28="", E28="", D28=""), "", IF(D28>TODAY(), "Applied", IF(G28<>"", IF(G28<E28, "Early Rejoin", "Rejoined"), IF(E28>TODAY(), "On Leave", "Not Rejoined")))) -> Rejoined | N28: =IF(AND(E28<>"", E28>=TODAY(), E28<=TODAY()+3), "Rejoin Follow Up", "") | O28: =IF(AND(G28<>"", G28 > E28, (G28 - E28) <> 1), G28 - E28, "") -> 21
A29: 835 | B29: =IFERROR(VLOOKUP(A29,'[1]Master File'!$A$2:$C$312,3,0)," ") -> Asim Abbas Sadiq Ali | C29: Annual Leave | D29: 45677 | E29: 45698 | F29: =IF(OR(D29="",E29 =""), "", E29 - D29+ 1) -> 22 | G29: 45699 | I29: =IF(AND(G29="", E29="", D29=""), "", IF(D29>TODAY(), "Applied", IF(G29<>"", IF(G29<E29, "Early Rejoin", "Rejoined"), IF(E29>TODAY(), "On Leave", "Not Rejoined")))) -> Rejoined | N29: =IF(AND(E29<>"", E29>=TODAY(), E29<=TODAY()+3), "Rejoin Follow Up", "") | O29: =IF(AND(G29<>"", G29 > E29, (G29 - E29) <> 1), G29 - E29, "")
A30: 1761 | B30: =IFERROR(VLOOKUP(A30,'[1]Master File'!$A$2:$C$312,3,0)," ") -> Syed Mushtaq Ahamad Syed Mukhtar Ahmed | C30: Annual Leave | D30: 45678 | E30: 45692 | F30: =IF(OR(D30="",E30 =""), "", E30 - D30+ 1) -> 15 | G30: 45693 | I30: =IF(AND(G30="", E30="", D30=""), "", IF(D30>TODAY(), "Applied", IF(G30<>"", IF(G30<E30, "Early Rejoin", "Rejoined"), IF(E30>TODAY(), "On Leave", "Not Rejoined")))) -> Rejoined | N30: =IF(AND(E30<>"", E30>=TODAY(), E30<=TODAY()+3), "Rejoin Follow Up", "") | O30: =IF(AND(G30<>"", G30 > E30, (G30 - E30) <> 1), G30 - E30, "")
A31: 2611 | B31: =IFERROR(VLOOKUP(A31,'[1]Master File'!$A$2:$C$312,3,0)," ") -> Sreejesh Kumar | C31: Annual Leave | D31: 45679 | E31: 45697 | F31: =IF(OR(D31="",E31 =""), "", E31 - D31+ 1) -> 19 | G31: 45699 | I31: =IF(AND(G31="", E31="", D31=""), "", IF(D31>TODAY(), "Applied", IF(G31<>"", IF(G31<E31, "Early Rejoin", "Rejoined"), IF(E31>TODAY(), "On Leave", "Not Rejoined")))) -> Rejoined | N31: =IF(AND(E31<>"", E31>=TODAY(), E31<=TODAY()+3), "Rejoin Follow Up", "") | O31: =IF(AND(G31<>"", G31 > E31, (G31 - E31) <> 1), G31 - E31, "") -> 2
A32: 333 | B32: =IFERROR(VLOOKUP(A32,'[1]Master File'!$A$2:$C$312,3,0)," ") -> Zohirul Islam Nuruzzaman | C32: Annual Leave | D32: 45682 | E32: 45712 | F32: =IF(OR(D32="",E32 =""), "", E32 - D32+ 1) -> 31 | G32: 45713 | I32: =IF(AND(G32="", E32="", D32=""), "", IF(D32>TODAY(), "Applied", IF(G32<>"", IF(G32<E32, "Early Rejoin", "Rejoined"), IF(E32>TODAY(), "On Leave", "Not Rejoined")))) -> Rejoined | N32: =IF(AND(E32<>"", E32>=TODAY(), E32<=TODAY()+3), "Rejoin Follow Up", "") | O32: =IF(AND(G32<>"", G32 > E32, (G32 - E32) <> 1), G32 - E32, "")
A33: 34 | B33: =IFERROR(VLOOKUP(A33,'[1]Master File'!$A$2:$C$312,3,0)," ") -> Ashok Kumar Lekhu Ram | C33: Emergency Leave | D33: 45685 | E33: 45715 | F33: =IF(OR(D33="",E33 =""), "", E33 - D33+ 1) -> 31 | G33: 45721 | I33: =IF(AND(G33="", E33="", D33=""), "", IF(D33>TODAY(), "Applied", IF(G33<>"", IF(G33<E33, "Early Rejoin", "Rejoined"), IF(E33>TODAY(), "On Leave", "Not Rejoined")))) -> Rejoined | N33: =IF(AND(E33<>"", E33>=TODAY(), E33<=TODAY()+3), "Rejoin Follow Up", "") | O33: =IF(AND(G33<>"", G33 > E33, (G33 - E33) <> 1), G33 - E33, "") -> 6
A34: 2632 | B34: =IFERROR(VLOOKUP(A34,'[1]Master File'!$A$2:$C$312,3,0)," ") -> Ratheesh Pv | C34: Annual Leave | D34: 45691 | E34: 45705 | F34: =IF(OR(D34="",E34 =""), "", E34 - D34+ 1) -> 15 | G34: 45706 | I34: =IF(AND(G34="", E34="", D34=""), "", IF(D34>TODAY(), "Applied", IF(G34<>"", IF(G34<E34, "Early Rejoin", "Rejoined"), IF(E34>TODAY(), "On Leave", "Not Rejoined")))) -> Rejoined | N34: =IF(AND(E34<>"", E34>=TODAY(), E34<=TODAY()+3), "Rejoin Follow Up", "") | O34: =IF(AND(G34<>"", G34 > E34, (G34 - E34) <> 1), G34 - E34, "")
A35: 1611 | B35: =IFERROR(VLOOKUP(A35,'[1]Master File'!$A$2:$C$312,3,0)," ") -> Sunil Rana | C35: Annual Leave | D35: 45691 | E35: 45698 | F35: =IF(OR(D35="",E35 =""), "", E35 - D35+ 1) -> 8 | G35: 45699 | I35: =IF(AND(G35="", E35="", D35=""), "", IF(D35>TODAY(), "Applied", IF(G35<>"", IF(G35<E35, "Early Rejoin", "Rejoined"), IF(E35>TODAY(), "On Leave", "Not Rejoined")))) -> Rejoined | N35: =IF(AND(E35<>"", E35>=TODAY(), E35<=TODAY()+3), "Rejoin Follow Up", "") | O35: =IF(AND(G35<>"", G35 > E35, (G35 - E35) <> 1), G35 - E35, "")
A36: 266 | B36: =IFERROR(VLOOKUP(A36,'[1]Master File'!$A$2:$C$312,3,0)," ") -> Shareef Asadullah Muhammad | C36: Annual Leave | D36: 45691 | E36: 45720 | F36: =IF(OR(D36="",E36 =""), "", E36 - D36+ 1) -> 30 | G36: 45715 | I36: =IF(AND(G36="", E36="", D36=""), "", IF(D36>TODAY(), "Applied", IF(G36<>"", IF(G36<E36, "Early Rejoin", "Rejoined"), IF(E36>TODAY(), "On Leave", "Not Rejoined")))) -> Early Rejoin | N36: =IF(AND(E36<>"", E36>=TODAY(), E36<=TODAY()+3), "Rejoin Follow Up", "") | O36: =IF(AND(G36<>"", G36 > E36, (G36 - E36) <> 1), G36 - E36, "")
A37: 1693 | B37: =IFERROR(VLOOKUP(A37,'[1]Master File'!$A$2:$C$312,3,0)," ") -> Shaik Rasheed Ahmed | C37: Emergency Leave | D37: 45691 | E37: 45694 | F37: =IF(OR(D37="",E37 =""), "", E37 - D37+ 1) -> 4 | G37: 45695 | I37: =IF(AND(G37="", E37="", D37=""), "", IF(D37>TODAY(), "Applied", IF(G37<>"", IF(G37<E37, "Early Rejoin", "Rejoined"), IF(E37>TODAY(), "On Leave", "Not Rejoined")))) -> Rejoined | N37: =IF(AND(E37<>"", E37>=TODAY(), E37<=TODAY()+3), "Rejoin Follow Up", "") | O37: =IF(AND(G37<>"", G37 > E37, (G37 - E37) <> 1), G37 - E37, "")
A38: 22 | B38: =IFERROR(VLOOKUP(A38,'[1]Master File'!$A$2:$C$312,3,0)," ") -> Alamgir Hossin Mohammed Sattar | C38: Annual Leave(Medical) | D38: 45693 | E38: 45707 | F38: =IF(OR(D38="",E38 =""), "", E38 - D38+ 1) -> 15 | G38: 45708 | I38: =IF(AND(G38="", E38="", D38=""), "", IF(D38>TODAY(), "Applied", IF(G38<>"", IF(G38<E38, "Early Rejoin", "Rejoined"), IF(E38>TODAY(), "On Leave", "Not Rejoined")))) -> Rejoined | N38: =IF(AND(E38<>"", E38>=TODAY(), E38<=TODAY()+3), "Rejoin Follow Up", "") | O38: =IF(AND(G38<>"", G38 > E38, (G38 - E38) <> 1), G38 - E38, "")
A39: 1399 | B39: =IFERROR(VLOOKUP(A39,'[1]Master File'!$A$2:$C$312,3,0)," ") -> Bachittar Singh | C39: Emergency Leave | D39: 45700 | E39: 45714 | F39: =IF(OR(D39="",E39 =""), "", E39 - D39+ 1) -> 15 | G39: 45729 | I39: =IF(AND(G39="", E39="", D39=""), "", IF(D39>TODAY(), "Applied", IF(G39<>"", IF(G39<E39, "Early Rejoin", "Rejoined"), IF(E39>TODAY(), "On Leave", "Not Rejoined")))) -> Rejoined | N39: =IF(AND(E39<>"", E39>=TODAY(), E39<=TODAY()+3), "Rejoin Follow Up", "") | O39: =IF(AND(G39<>"", G39 > E39, (G39 - E39) <> 1), G39 - E39, "") -> 15
A40: 2738 | B40: Zabiullah Khan | C40: Emergency Leave | D40: 45703 | E40: 45718 | F40: =IF(OR(D40="",E40 =""), "", E40 - D40+ 1) -> 16 | G40: 45719 | I40: =IF(AND(G40="", E40="", D40=""), "", IF(D40>TODAY(), "Applied", IF(G40<>"", IF(G40<E40, "Early Rejoin", "Rejoined"), IF(E40>TODAY(), "On Leave", "Not Rejoined")))) -> Rejoined | N40: =IF(AND(E40<>"", E40>=TODAY(), E40<=TODAY()+3), "Rejoin Follow Up", "") | O40: =IF(AND(G40<>"", G40 > E40, (G40 - E40) <> 1), G40 - E40, "")
...

Sheet Leave report
A1: Employee ID | B1: Name | C1: EML | D1: AL
A2: 2626 | B2: Sanjeev Dubey | C2: 31
A3: 2613 | B3: Amrish Pandey | C3: 31
A4: 2314 | B4: Vinod Sohan | C4: 25 | D4: 6
A5: 2834 | B5: Virendra Singh | C5: 31
A6: 2516 | B6: Rajesh Kumar Choudhary | D6: 31
A7: 2510 | B7: Sanjay Kumar | D7: 31
A8: 2856 | B8: Laxman Armoori | C8: 31
A9: 2707 | B9: Mosim Khan | D9: 28
A10: 2740 | B10: Jagedeesh | C10: 22 | D10: 9
A11: 2594 | B11: Naveed Shams Ur Rehman | C11: 10 | D11: 21 | F11: 46102 | G11: 46122 | H11: =G11-F11+1 -> 21
A12: 976 | B12: Nasar Khan Muhammad Afzal Khan | D12: 29 | F12: 46104 | G12: 46132 | H12: =G12-F12+1 -> 29
A13: 1016 | B13: Mohammed Abul Hasan | D13: 30
A14: 2752 | B14: Madhavkumar | C14: 18
A15: 227 | B15: Rezaul Karim Abdur Rouf | C15: 31
A16: 2478 | B16: Saqib Raza | D16: 22
A17: 2627 | B17: Bheem Kumar Thakur | D17: 31
A18: 2504 | B18: Muhammad Tayyab | D18: 29
A19: 2622 | B19: Ahtsham Khalid | D19: 26
A20: 1076 | B20: Naveed Anjum Muhammad Ramzan Bagoo | D20: 26
A21: 629 | B21: Amir Alam Khan Bahar Karam | D21: 22
A22: 2537 | B22: Rasel Ali Sha | D22: 31
A23: 2014 | B23: Bacha Rashid Fazal Wahid | C23: 10
A24: 2887 | B24: Govindu Ari | C24: 10
A25: 2407 | B25: Radhakrishnan Ramankutty | D25: 4
A26: 1856 | B26: Kumar Gautam Kamal Kishore Prasad | D26: 8
A27: 2845 | B27: Jafar Ali | D27: 1
A28: 1399 | B28: Bachittar Singh | D28: 31
A29: 2777 | B29: Prasantha Kumar | C29: 9 | D29: 18
A30: 338 | B30: Jugdayal Sharma Sudeshwar Sharma | C30: 14 | D30: 11
A31: 979 | B31: Gopakumar Gopinathan Pillai | D31: 11
A32: 2656 | B32: Amith V.R | D32: 17
A33: 1693 | B33: Shaik Rasheed Ahmed | D33: 18 | F33: 46104 | G33: 46121 | H33: =G33-F33+1 -> 18
A34: 1617 | B34: Mohammed Mubeen Mahmood Ali | D34: 4
A35: 2471 | B35: Gobri Yadav | C35: 3
A36: 2798 | B36: SUNNY JAIPAL | C36: 31
A37: 1402 | B37: khushali | C37: 18 | D37: 6
A38: 2636 | B38: SANJOGA THAPA | C38: 14
A39: 1884 | B39: Akhin Varghese | D39: 1
A40: 231 | B40: Rashid Sheikh | D40: 26
...

Sheet Annual Leave Balance
A1: Annual Leave Balance
A2: Employee ID | B2: Name | C2: Designation | D2: Join Date | E2: As On | F2: Total Days | G2: Service Days | H2: EXT Day | I2: EML | J2: Balance on 12/24 | K2: Elgible | L2: Leave Taken | M2: AL Balance | N2: Leave taken in 2025 | O2: Balance | P2: Remarks
A3: 14 | B3: Afroz Ali Khan Khan | C3: Cashier | D3: 39221 | E3: =TODAY() -> 46195 | F3: =E3-D3 -> 6974 | G3: =F3-(H3+I3) -> 6916 | H3: 53 | I3: 5 | J3: 97.5 | K3: =G3/360*30 -> 576.33333 | L3: 434 | M3: =K3-L3 -> 142.33333 | N3: =SUMIFS('Leave Tracker'!F:F,'Leave Tracker'!A:A,'Annual Leave Balance'!A3,'Leave Tracker'!C:C,"Annual Leave") -> 30 | O3: =M3-N3 -> 112.33333
A4: 22 | B4: Alamgir Hossin Mohammed Sattar | C4: Carpenter | D4: 38298 | E4: =TODAY() -> 46195 | F4: =E4-D4 -> 7897 | G4: =F4-(H4+I4) -> 7805 | H4: 92 | I4: 0 | J4: 132.58333 | K4: =G4/360*30 -> 650.41667 | L4: 473 | M4: =K4-L4 -> 177.41667 | N4: =SUMIFS('Leave Tracker'!F:F,'Leave Tracker'!A:A,'Annual Leave Balance'!A4,'Leave Tracker'!C:C,"Annual Leave") -> 61 | O4: =M4-N4 -> 116.41667
A5: 23 | B5: Amanutullah Khan | C5: Aluminium Fabricator | D5: 39277 | E5: =TODAY() -> 46195 | F5: =E5-D5 -> 6918 | G5: =F5-(H5+I5) -> 6740 | H5: 178 | I5: 0 | J5: 173.83333 | K5: =G5/360*30 -> 561.66667 | L5: 343 | M5: =K5-L5 -> 218.66667 | N5: =SUMIFS('Leave Tracker'!F:F,'Leave Tracker'!A:A,'Annual Leave Balance'!A5,'Leave Tracker'!C:C,"Annual Leave") -> 60 | O5: =M5-N5 -> 158.66667
A6: 34 | B6: Ashok Kumar Lekhu Ram | C6: Online QC | D6: 39508 | E6: 46159 | F6: =E6-D6 -> 6651 | G6: =F6-(H6+I6) -> 6240 | H6: 309 | I6: 102 | J6: 3.25 | K6: =G6/360*30 -> 520 | L6: 480 | M6: =K6-L6 -> 40 | N6: =SUMIFS('Leave Tracker'!F:F,'Leave Tracker'!A:A,'Annual Leave Balance'!A6,'Leave Tracker'!C:C,"Annual Leave") -> 33 | O6: =M6-N6 -> 7
A7: 41 | B7: Babuu Ansar Ali | C7: Extruder Operator | D7: 38361 | E7: =TODAY() -> 46195 | F7: =E7-D7 -> 7834 | G7: =F7-(H7+I7) -> 7763 | H7: 71 | I7: 0 | J7: -0.91666667 | K7: =G7/360*30 -> 646.91667 | L7: 580 | M7: =K7-L7 -> 66.916667 | N7: =SUMIFS('Leave Tracker'!F:F,'Leave Tracker'!A:A,'Annual Leave Balance'!A7,'Leave Tracker'!C:C,"Annual Leave") -> 60 | O7: =M7-N7 -> 6.9166667
A8: 67 | B8: Esoj Jose | C8: Electrical Supervisor | D8: 39358 | E8: =TODAY() -> 46195 | F8: =E8-D8 -> 6837 | G8: =F8-(H8+I8) -> 6727 | H8: 52 | I8: 58 | J8: 133.75 | K8: =G8/360*30 -> 560.58333 | L8: 382 | M8: =K8-L8 -> 178.58333 | N8: =SUMIFS('Leave Tracker'!F:F,'Leave Tracker'!A:A,'Annual Leave Balance'!A8,'Leave Tracker'!C:C,"Annual Leave") -> 30 | O8: =M8-N8 -> 148.58333
A9: 68 | B9: Esrafil Patu Ali | C9: Mason | D9: 38980 | E9: =TODAY() -> 46195 | F9: =E9-D9 -> 7215 | G9: =F9-(H9+I9) -> 7214 | H9: 1 | I9: 0 | J9: 227.33333 | K9: =G9/360*30 -> 601.16667 | L9: 329 | M9: =K9-L9 -> 272.16667 | N9: =SUMIFS('Leave Tracker'!F:F,'Leave Tracker'!A:A,'Annual Leave Balance'!A9,'Leave Tracker'!C:C,"Annual Leave") -> 30 | O9: =M9-N9 -> 242.16667
A10: 81 | B10: Gulak Sutradhar Babu Lal | C10: Foreman | D10: 38361 | E10: =TODAY() -> 46195 | F10: =E10-D10 -> 7834 | G10: =F10-(H10+I10) -> 7814 | H10: 20 | I10: 0 | J10: 279.33333 | K10: =G10/360*30 -> 651.16667 | L10: 327 | M10: =K10-L10 -> 324.16667 | N10: =SUMIFS('Leave Tracker'!F:F,'Leave Tracker'!A:A,'Annual Leave Balance'!A10,'Leave Tracker'!C:C,"Annual Leave") -> 0 | O10: =M10-N10 -> 324.16667
A11: 93 | B11: Esmaeil Hassan Rahideh | C11: Group Director – Legal & Communications | D11: 39480 | E11: =TODAY() -> 46195 | F11: =E11-D11 -> 6715 | G11: =F11-(H11+I11) -> 6684 | H11: 31 | I11: 0 | J11: 301.16667 | K11: =G11/360*30 -> 557 | L11: 211 | M11: =K11-L11 -> 346 | N11: =SUMIFS('Leave Tracker'!F:F,'Leave Tracker'!A:A,'Annual Leave Balance'!A11,'Leave Tracker'!C:C,"Annual Leave") -> 0 | O11: 264
A12: 102 | B12: Jayesh Krishnan Gopalakrishnan | C12: Sales Executive | D12: 38964 | E12: =TODAY() -> 46195 | F12: =E12-D12 -> 7231 | G12: =F12-(H12+I12) -> 7207 | H12: 7 | I12: 17 | J12: 105.75 | K12: =G12/360*30 -> 600.58333 | L12: 450 | M12: =K12-L12 -> 150.58333 | N12: =SUMIFS('Leave Tracker'!F:F,'Leave Tracker'!A:A,'Annual Leave Balance'!A12,'Leave Tracker'!C:C,"Annual Leave") -> 29 | O12: =M12-N12 -> 121.58333
A13: 116 | B13: Khorshed Sheikh Nurul Islam | C13: FR Helper Line 3 | D13: 39455 | E13: =TODAY() -> 46195 | F13: =E13-D13 -> 6740 | G13: =F13-(H13+I13) -> 6662 | H13: 78 | I13: 0 | J13: 205.33333 | K13: =G13/360*30 -> 555.16667 | L13: 305 | M13: =K13-L13 -> 250.16667 | N13: =SUMIFS('Leave Tracker'!F:F,'Leave Tracker'!A:A,'Annual Leave Balance'!A13,'Leave Tracker'!C:C,"Annual Leave") -> 0 | O13: =M13-N13 -> 250.16667
A14: 142 | B14: Mary Jaya Francis | C14: Executive Manager – Chairman’s Office | D14: 38936 | E14: =TODAY() -> 46195 | F14: =E14-D14 -> 7259 | G14: =F14-(H14+I14) -> 7259 | H14: 0 | I14: 0 | J14: 239.08333 | K14: =G14/360*30 -> 604.91667 | L14: 321 | M14: =K14-L14 -> 283.91667 | N14: =SUMIFS('Leave Tracker'!F:F,'Leave Tracker'!A:A,'Annual Leave Balance'!A14,'Leave Tracker'!C:C,"Annual Leave") -> 36 | O14: =M14-N14 -> 247.91667 | P14: as on Apr 44
A15: 147 | B15: Md Mosharaf Hossain | C15: Production Supervisor | D15: 39370 | E15: =TODAY() -> 46195 | F15: =E15-D15 -> 6825 | G15: =F15-(H15+I15) -> 6782 | H15: 43 | I15: 0 | J15: 143.33333 | K15: =G15/360*30 -> 565.16667 | L15: 377 | M15: =K15-L15 -> 188.16667 | N15: =SUMIFS('Leave Tracker'!F:F,'Leave Tracker'!A:A,'Annual Leave Balance'!A15,'Leave Tracker'!C:C,"Annual Leave") -> 0 | O15: =M15-N15 -> 188.16667
A16: 166 | B16: Muhammad Inam Noor Muhammad | C16: Chairman Driver | D16: 38976 | E16: 46022 | F16: =E16-D16 -> 7046 | G16: =F16-(H16+I16) -> 6993 | H16: 53 | I16: 0 | J16: 70.333333 | K16: =G16/360*30 -> 582.75 | L16: 482 | M16: =K16-L16 -> 100.75 | N16: =SUMIFS('Leave Tracker'!F:F,'Leave Tracker'!A:A,'Annual Leave Balance'!A16,'Leave Tracker'!C:C,"Annual Leave") -> 62 | O16: =M16-N16 -> 38.75
A17: 190 | B17: Nasir Aziz Masih Aziz | C17: Sales Executive / Cricketer | D17: 38969 | E17: =TODAY() -> 46195 | F17: =E17-D17 -> 7226 | G17: =F17-(H17+I17) -> 7196 | H17: 6 | I17: 24 | J17: 206.83333 | K17: =G17/360*30 -> 599.66667 | L17: 348 | M17: =K17-L17 -> 251.66667 | N17: =SUMIFS('Leave Tracker'!F:F,'Leave Tracker'!A:A,'Annual Leave Balance'!A17,'Leave Tracker'!C:C,"Annual Leave") -> 9 | O17: =M17-N17 -> 242.66667
A18: 194 | B18: Olyullah Ali Akbor | C18: Supervisor | D18: 38620 | E18: =TODAY() -> 46195 | F18: =E18-D18 -> 7575 | G18: =F18-(H18+I18) -> 7434 | H18: 141 | I18: 0 | J18: 242.66667 | K18: =G18/360*30 -> 619.5 | L18: 332 | M18: =K18-L18 -> 287.5 | N18: =SUMIFS('Leave Tracker'!F:F,'Leave Tracker'!A:A,'Annual Leave Balance'!A18,'Leave Tracker'!C:C,"Annual Leave") -> 35 | O18: =M18-N18 -> 252.5
A19: 225 | B19: Ravikumar Velayudhan Velayudhan | C19: Production Supervisor | D19: 39452 | E19: =TODAY() -> 46195 | F19: =E19-D19 -> 6743 | G19: =F19-(H19+I19) -> 6724 | H19: 19 | I19: 0 | J19: 91.5 | K19: =G19/360*30 -> 560.33333 | L19: 424 | M19: =K19-L19 -> 136.33333 | N19: =SUMIFS('Leave Tracker'!F:F,'Leave Tracker'!A:A,'Annual Leave Balance'!A19,'Leave Tracker'!C:C,"Annual Leave") -> 0 | O19: =M19-N19 -> 136.33333
A20: 227 | B20: Rezaul Karim Abdur Rouf | C20: Extruder Operator | D20: 39365 | E20: =TODAY() -> 46195 | F20: =E20-D20 -> 6830 | G20: =F20-(H20+I20) -> 6511 | H20: 289 | I20: 30 | J20: 10.75 | K20: =G20/360*30 -> 542.58333 | L20: 487 | M20: =K20-L20 -> 55.583333 | N20: =SUMIFS('Leave Tracker'!F:F,'Leave Tracker'!A:A,'Annual Leave Balance'!A20,'Leave Tracker'!C:C,"Annual Leave") -> 0 | O20: =M20-N20 -> 55.583333
A21: 231 | B21: Roshid Sheikh Taleb Ali Sheikh | C21: Helper | D21: 38980 | E21: =TODAY() -> 46195 | F21: =E21-D21 -> 7215 | G21: =F21-(H21+I21) -> 7117 | H21: 98 | I21: 0 | J21: 134.25 | K21: =G21/360*30 -> 593.08333 | L21: 414 | M21: =K21-L21 -> 179.08333 | N21: =SUMIFS('Leave Tracker'!F:F,'Leave Tracker'!A:A,'Annual Leave Balance'!A21,'Leave Tracker'!C:C,"Annual Leave") -> 0 | O21: =M21-N21 -> 179.08333
A22: 232 | B22: Ruhul Amin Haian Saiyal | C22: End Cutting Operator | D22: 39442 | E22: =TODAY() -> 46195 | F22: =E22-D22 -> 6753 | G22: =F22-(H22+I22) -> 6664 | H22: 89 | I22: 0 | J22: 74.5 | K22: =G22/360*30 -> 555.33333 | L22: 436 | M22: =K22-L22 -> 119.33333 | N22: =SUMIFS('Leave Tracker'!F:F,'Leave Tracker'!A:A,'Annual Leave Balance'!A22,'Leave Tracker'!C:C,"Annual Leave") -> 60 | O22: =M22-N22 -> 59.333333
A23: 234 | B23: Saidur Abdul Samad | C23: Lamination Operator | D23: 38388 | E23: =TODAY() -> 46195 | F23: =E23-D23 -> 7807 | G23: =F23-(H23+I23) -> 7427 | H23: 349 | I23: 31 | J23: 107.08333 | K23: =G23/360*30 -> 618.91667 | L23: 467 | M23: =K23-L23 -> 151.91667 | N23: =SUMIFS('Leave Tracker'!F:F,'Leave Tracker'!A:A,'Annual Leave Balance'!A23,'Leave Tracker'!C:C,"Annual Leave") -> 61 | O23: =M23-N23 -> 90.916667
A24: 235 | B24: Saiyed Anwar Hussain Rizvi | C24: Senior Manager | D24: 38808 | E24: =TODAY() -> 46195 | F24: =E24-D24 -> 7387 | G24: =F24-(H24+I24) -> 7399 | H24: -12 | I24: 0 | J24: 225.75 | K24: =G24/360*30 -> 616.58333 | L24: 346 | M24: =K24-L24 -> 270.58333 | N24: =SUMIFS('Leave Tracker'!F:F,'Leave Tracker'!A:A,'Annual Leave Balance'!A24,'Leave Tracker'!C:C,"Annual Leave") -> 27 | O24: =M24-N24 -> 243.58333
A25: 266 | B25: Shareef Asadullah Muhammad | C25: PR Manager | D25: 39337 | E25: =TODAY() -> 46195 | F25: =E25-D25 -> 6858 | G25: =F25-(H25+I25) -> 6797 | H25: 61 | I25: 0 | J25: 105.58333 | K25: =G25/360*30 -> 566.41667 | L25: 416 | M25: =K25-L25 -> 150.41667 | N25: =SUMIFS('Leave Tracker'!F:F,'Leave Tracker'!A:A,'Annual Leave Balance'!A25,'Leave Tracker'!C:C,"Annual Leave") -> 48 | O25: =M25-N25 -> 102.41667
A26: 276 | B26: Shoukath Ahmed Khan | C26: Security Guard | D26: 39062 | E26: =TODAY() -> 46195 | F26: =E26-D26 -> 7133 | G26: =F26-(H26+I26) -> 6937 | H26: 196 | I26: 0 | J26: 108.25 | K26: =G26/360*30 -> 578.08333 | L26: 425 | M26: =K26-L26 -> 153.08333 | N26: =SUMIFS('Leave Tracker'!F:F,'Leave Tracker'!A:A,'Annual Leave Balance'!A26,'Leave Tracker'!C:C,"Annual Leave") -> 0 | O26: =M26-N26 -> 153.08333
A27: 279 | B27: Siful Islam Abdul Samad | C27: Production Supervisor | D27: 38682 | E27: =TODAY() -> 46195 | F27: =E27-D27 -> 7513 | G27: =F27-(H27+I27) -> 7376 | H27: 90 | I27: 47 | J27: -18.166667 | K27: =G27/360*30 -> 614.66667 | L27: 588 | M27: =K27-L27 -> 26.666667 | N27: =SUMIFS('Leave Tracker'!F:F,'Leave Tracker'!A:A,'Annual Leave Balance'!A27,'Leave Tracker'!C:C,"Annual Leave") -> 111 | O27: =M27-N27 -> -84.333333
A28: 310 | B28: Vijayalekshmi Neelakanta Pillai Sajeev Kumar | C28: Temporary Forklift Operator | D28: 39061 | E28: =TODAY() -> 46195 | F28: =E28-D28 -> 7134 | G28: =F28-(H28+I28) -> 6887 | H28: 247 | I28: 0 | J28: -12.916667 | K28: =G28/360*30 -> 573.91667 | L28: 542 | M28: =K28-L28 -> 31.916667 | N28: =SUMIFS('Leave Tracker'!F:F,'Leave Tracker'!A:A,'Annual Leave Balance'!A28,'Leave Tracker'!C:C,"Annual Leave") -> 62 | O28: =M28-N28 -> -30.083333
... A31: 334 | B31: Zulfikar Ali Abdul Majeed | C31: Regional Manager | D31: 38476 | E31: =TODAY() -> 46195 | F31: =E31-D31 -> 7719 | G31: =F31-(H31+I31) -> 7656 | H31: 63 | I31: 0 | J31: 262.16667 | K31: =G31/360*30 -> 638 | L31: 331 | M31: =K31-L31 -> 307 | N31: =SUMIFS('Leave Tracker'!F:F,'Leave Tracker'!A:A,'Annual Leave Balance'!A31,'Leave Tracker'!C:C,"Annual Leave") -> 13 | O31: =M31-N31 -> 294
A32: 338 | B32: Jugdayal Sharma Sudeshwar Sharma | C32: Foreman | D32: 42747 | E32: =TODAY() -> 46195 | F32: =E32-D32 -> 3448 | G32: =F32-(H32+I32) -> 3276 | H32: 172 | I32: 0 | J32: 25.166667 | K32: =G32/360*30 -> 273 | L32: 203 | M32: =K32-L32 -> 70 | N32: 62 | O32: =M32-N32 -> 8
A33: 351 | B33: Shameem Hossain Mofser Mollah | C33: Supervisor | D33: 39547 | E33: =TODAY() -> 46195 | F33: =E33-D33 -> 6648 | G33: =F33-(H33+I33) -> 6645 | H33: 3 | I33: 0 | J33: 91.916667 | K33: =G33/360*30 -> 553.75 | L33: 417 | M33: =K33-L33 -> 136.75 | N33: =SUMIFS('Leave Tracker'!F:F,'Leave Tracker'!A:A,'Annual Leave Balance'!A33,'Leave Tracker'!C:C,"Annual Leave") -> 63 | O33: =M33-N33 -> 73.75
A34: 356 | B34: Balwant Singh Munsha Singh | C34: Helper | D34: 39568 | E34: =TODAY() -> 46195 | F34: =E34-D34 -> 6627 | G34: =F34-(H34+I34) -> 6518 | H34: 94 | I34: 15 | J34: 199.33333 | K34: =G34/360*30 -> 543.16667 | L34: 299 | M34: =K34-L34 -> 244.16667 | N34: =SUMIFS('Leave Tracker'!F:F,'Leave Tracker'!A:A,'Annual Leave Balance'!A34,'Leave Tracker'!C:C,"Annual Leave") -> 59 | O34: =M34-N34 -> 185.16667
A35: 360 | B35: Moazam Qureshi Mohammed | C35: Asst. Operation Manager | D35: 39578 | E35: =TODAY() -> 46195 | F35: =E35-D35 -> 6617 | G35: =F35-(H35+I35) -> 6605 | H35: 12 | I35: 0 | J35: 185.58333 | K35: =G35/360*30 -> 550.41667 | L35: 320 | M35: =K35-L35 -> 230.41667 | N35: =SUMIFS('Leave Tracker'!F:F,'Leave Tracker'!A:A,'Annual Leave Balance'!A35,'Leave Tracker'!C:C,"Annual Leave") -> 20 | O35: =M35-N35 -> 210.41667
A36: 363 | B36: Badri Bahadur Budhathoki | C36: Security Guard | D36: 39576 | E36: =TODAY() -> 46195 | F36: =E36-D36 -> 6619 | G36: =F36-(H36+I36) -> 6539 | H36: 64 | I36: 16 | J36: 169.08333 | K36: =G36/360*30 -> 544.91667 | L36: 331 | M36: =K36-L36 -> 213.91667 | N36: =SUMIFS('Leave Tracker'!F:F,'Leave Tracker'!A:A,'Annual Leave Balance'!A36,'Leave Tracker'!C:C,"Annual Leave") -> 0 | O36: =M36-N36 -> 213.91667
A37: 367 | B37: Ratan Sheikh Nurul Islam | C37: House Keeper | D37: 39599 | E37: =TODAY() -> 46195 | F37: =E37-D37 -> 6596 | G37: =F37-(H37+I37) -> 6480 | H37: 86 | I37: 30 | J37: 122.16667 | K37: =G37/360*30 -> 540 | L37: 373 | M37: =K37-L37 -> 167 | N37: =SUMIFS('Leave Tracker'!F:F,'Leave Tracker'!A:A,'Annual Leave Balance'!A37,'Leave Tracker'!C:C,"Annual Leave") -> 0 | O37: =M37-N37 -> 167
A38: 379 | B38: Mirza Shafiullah Baig | C38: Purchase Assistant | D38: 39641 | E38: =TODAY() -> 46195 | F38: =E38-D38 -> 6554 | G38: =F38-(H38+I38) -> 6156 | H38: 398 | I38: 0 | J38: 136.16667 | K38: =G38/360*30 -> 513 | L38: 332 | M38: =K38-L38 -> 181 | N38: =SUMIFS('Leave Tracker'!F:F,'Leave Tracker'!A:A,'Annual Leave Balance'!A38,'Leave Tracker'!C:C,"Annual Leave") -> 30 | O38: =M38-N38 -> 151
A39: 389 | B39: Mehedi Hasan Abdul Aziz | C39: Office Boy | D39: 39654 | E39: =TODAY() -> 46195 | F39: =E39-D39 -> 6541 | G39: =F39-(H39+I39) -> 6410 | H39: 131 | I39: 0 | J39: 55.333333 | K39: =G39/360*30 -> 534.16667 | L39: 434 | M39: =K39-L39 -> 100.16667 | N39: =SUMIFS('Leave Tracker'!F:F,'Leave Tracker'!A:A,'Annual Leave Balance'!A39,'Leave Tracker'!C:C,"Annual Leave") -> 0 | O39: =M39-N39 -> 100.16667
A40: 394 | B40: Kamal Hossain Tofazzal Mollah | C40: House Keeper | D40: 39649 | E40: =TODAY() -> 46195 | F40: =E40-D40 -> 6546 | G40: =F40-(H40+I40) -> 6348 | H40: 168 | I40: 30 | J40: 123.16667 | K40: =G40/360*30 -> 529 | L40: 361 | M40: =K40-L40 -> 168 | N40: =SUMIFS('Leave Tracker'!F:F,'Leave Tracker'!A:A,'Annual Leave Balance'!A40,'Leave Tracker'!C:C,"Annual Leave") -> 62 | O40: =M40-N40 -> 106
A41: 399 | B41: Mohammed Parvez Kamal Uddin | C41: End Cutting Operator | D41: 39659 | E41: =TODAY() -> 46195 | F41: =E41-D41 -> 6536 | G41: =F41-(H41+I41) -> 6403 | H41: 115 | I41: 18 | J41: 187.75 | K41: =G41/360*30 -> 533.58333 | L41: 301 | M41: =K41-L41 -> 232.58333 | N41: =SUMIFS('Leave Tracker'!F:F,'Leave Tracker'!A:A,'Annual Leave Balance'!A41,'Leave Tracker'!C:C,"Annual Leave") -> 67 | O41: =M41-N41 -> 165.58333
A42: 434 | B42: Liton Zamal Hossain | C42: Lamination Operator | D42: 39742 | E42: =TODAY() -> 46195 | F42: =E42-D42 -> 6453 | G42: =F42-(H42+I42) -> 6439 | H42: 14 | I42: 0 | J42: 100.75 | K42: =G42/360*30 -> 536.58333 | L42: 391 | M42: =K42-L42 -> 145.58333 | N42: =SUMIFS('Leave Tracker'!F:F,'Leave Tracker'!A:A,'Annual Leave Balance'!A42,'Leave Tracker'!C:C,"Annual Leave") -> 0 | O42: =M42-N42 -> 145.58333
...
